Workbook

Sheet Leeme
A1: APAR-CAR - Backlog del producto v3.5
A2: Proyecto de grado - Tecnólogo en Análisis y Desarrollo de Software - Ficha 3229209 - SENA | Instructor: Deimer Miranda Montoya | Equipo: Ismael Mira Correa (frontend) | Valeria Usuga Penagos (backend) | Mariana Uribe Muñoz (analista y líder)
A3: Actualizado el 11 de septiembre de 2026. Entregable 3 del proyecto: documento de Backlog, Historias de Usuario y Casos de Uso. La v3.5 incorpora a HU-43 el criterio de aceptación sobre el acuse al dispositivo lector, detectado durante el modelado de la plantilla P04.
A5: QUE HAY EN ESTE LIBRO
A6: Resumen | B6: Métricas del backlog calculadas con fórmulas: total de puntos, reparto MoSCoW y porcentaje de esfuerzo en Must. Es lo que se mira primero para saber si el alcance de la primera versión es realista.
A7: Actores | B7: Quién usa el sistema, que necesita lograr y por qué le importa. Cada actor esta cruzado con su stakeholder (STK) del documento de Stakeholders.
A8: Épicas | B8: 8 épicas agrupadas por CAPACIDAD del sistema, no por pantalla. Los conteos y los puntos se calculan solos desde la hoja Historias de Usuario.
A9: Requisitos Funcionales | B9: 22 requisitos (RF-xx) con su origen y las historias que los implementan. Hoja nueva en la v3.2: el catálogo vivía únicamente en el Anexo A de la plantilla P01.
A10: Historias de Usuario | B10: 47 historias con criterios de aceptación en Dado/Cuando/Entonces y un escenario de error propio por historia. Es la hoja principal del libro.
A11: Reglas de Negocio | B11: 17 reglas (RN-xx) que aplican siempre, independientes de la pantalla. Se separan de las historias para no repetirlas en cada criterio de aceptación.
A12: Requisitos No Funcionales | B12: 11 requisitos (RNF-xx) con criterio de verificación y su riesgo asociado del documento Análisis de Seguridad. Un RNF que no se puede verificar no es un requisito.
A13: INVEST | B13: Checklist INVEST por historia, con observación donde hay algo que revisar.
A14: Trazabilidad | B14: Cadena Necesidad -> Stakeholder -> Épica -> Historia -> Regla/RNF -> Caso de prueba. Es el esqueleto de la matriz de trazabilidad de la fase de pruebas.
A15: Decisiones (ADR) | B15: 10 decisiones de arquitectura registradas, con alternativas evaluadas y consecuencias. Todas aceptadas: ADR-008 (stack tecnologico) se cerro el 11/09/2026 y ADR-010 (estilo arquitectonico) se creo en la v3.4.
A16: Fuera de alcance | B16: Lo que se decidió NO hacer y por qué. Documentar esto vale tanto como documentar lo que si se hace.
A17: Control de cambios | B17: Que cambio de la v2 a la v3, con su justificación. Incluye las correcciones pendientes en los demás entregables del proyecto.
... A20: Supuestos | B20: SUP-03: condiciones que se dan por ciertas y de las que dependen partes del alcance. Si un supuesto se cae, se cae lo que sostiene.
A22: COMO SE USA
A23: Celdas amarillas | B23: Son las que el equipo debe diligenciar o confirmar. Todo lo demás ya viene propuesto.
A24: Columna Estado | B24: Lista desplegable: Por hacer / En progreso / En revisión / Hecho. Es lo que se refleja en el tablero del equipo.
A25: Columnas MoSCoW y Puntos | B25: Listas desplegables. Si se cambia un valor, el Resumen y las Épicas se recalculan solos.
A26: Historia de referencia | B26: HU-04 (Cerrar mi sesión) anclada en 2 puntos. Todas las demás se estimaron comparándose con ella.
A27: Puntos, no horas | B27: La estimación es relativa. Un 8 es cuatro veces más grande que un 2, pero no equivale a un número fijo de horas.
A29: QUE CAMBIO FRENTE A LA v2 (detalle completo en la hoja Control de cambios)
A30: Nombre del proyecto | B30: El libro decía UrbanSpot. El proyecto se llama APAR-CAR y la ficha correcta es 3229209.
A31: Rol de operario | B31: Entra a la primera versión. El Acta de Constitución lo promete en el objetivo general y en el Entregable 5, y el documento de Stakeholders lo clasifica como STK-02 usuario clave. Antes estaba fuera de alcance: era una contradicción entre entregables.
A32: Visitante ocasional | B32: Deja de ser un actor pasivo. Ahora puede consultar su tiquete con un código entregado a la entrada, nunca con la placa (STK-04).
A33: Reglas de cobro | B33: RN-14 quedo definida: cobro proporcional por bloques de 24 horas, cobrando por bloque el menor entre el proporcional y la tarifa día, con cobro mínimo de una hora.
A34: Derecho de supresión | B34: HU-37 pasa de eliminar a inhabilitar y luego anonimizar, amparada en el deber contractual que reconoce la propia norma. Los registros de dinero sobreviven sin titular identificable.
A35: Historias divisibles | B35: HU-12 se dividió en HU-12a y HU-12b. HU-21 se mantiene unida con justificación escrita.
A36: Aviso de vencimiento | B36: La antigua HU-31 se retiro del alcance: exige un proceso programado y un servicio de correo que no aportan al nucleo de la v1.
A37: Decisiones cerradas | B37: Los supuestos SUP-01 y SUP-02 desaparecen. ADR-003 y ADR-004 pasan a Aceptada y se agregan ADR-005, ADR-006 y ADR-007.
A38: Trazabilidad ampliada | B38: Cada historia y cada necesidad quedan cruzadas con el stakeholder que la origina, y cada RNF con el riesgo del Análisis de Seguridad que mitiga.
A40: DECISIONES CERRADAS EL 14 DE AGOSTO DE 2026
A41: Modelo de espacios | B41: Celdas identificadas con código propio (A-01, A-02), no un contador. Confirmado por el Acta de Constitución. Ver ADR-003.
A42: Ciclo de facturación | B42: Rodante: 30 días calendario desde la fecha del pago. Evita el prorrateo. Ver ADR-004 y RN-11.
A43: Código de vinculación | B43: Vence a los 7 días. Ver RN-05.
A44: Estado Por vencer | B44: Se activa 3 días antes del vencimiento. Ver RN-12.
A45: Roles del sistema | B45: Tres roles con credenciales: administrador, operario y cliente afiliado. A ellos se suman Persona nueva y Cliente ocasional como actores sin rol. Ver ADR-005.
A47: PENDIENTE DE DILIGENCIAR POR EL EQUIPO
...

Sheet Resumen
A1: Resumen del backlog
A2: APAR-CAR v3.5 - Proyecto de grado - Tecnólogo en Análisis y Desarrollo de Software - Ficha 3229209. Actualizado el 11 de septiembre de 2026.
A3: Todo en esta hoja se calcula con fórmulas desde las demás hojas. No escriba valores a mano aquí.
A4: Indicador | B4: Valor | C4: Nota
A5: Total de historias de usuario | B5: =COUNTIF('Historias de Usuario'!$A$5:$A$200,"HU-*") -> 47 | C5: Mínimo exigido por la guía: 8
A6: Roles del sistema (con credenciales) | B6: 3 | C6: Administrador, Operario y Cliente afiliado. Mínimo exigido por la guía: 2
A7: Actores del sistema | B7: 5 | C7: Los 3 roles más Persona nueva y Cliente ocasional. Son los que aparecen en BPMN, secuencia y actividades
A8: Total de puntos del proyecto | B8: =SUM('Historias de Usuario'!$K$5:$K$200) -> 187 | C8: Estimación relativa, no horas
A9: Puntos en Must | B9: =SUMIF('Historias de Usuario'!$J$5:$J$200,"Must",'Historias de Usuario'!$K$5:$K$200) -> 111 | C9: Producto mínimo viable
A10: Puntos en Should | B10: =SUMIF('Historias de Usuario'!$J$5:$J$200,"Should",'Historias de Usuario'!$K$5:$K$200) -> 55 | C10: Importante, no bloqueante
A11: Puntos en Could | B11: =SUMIF('Historias de Usuario'!$J$5:$J$200,"Could",'Historias de Usuario'!$K$5:$K$200) -> 21 | C11: Si sobra capacidad
A12: % de esfuerzo en Must | B12: =IFERROR(B9/B8,0) -> 0.59358289 | C12: Referencia sana: entre 50% y 65%. Por encima de 70% el alcance del MVP está inflado
A13: Historias Must | B13: =COUNTIF('Historias de Usuario'!$J$5:$J$200,"Must") -> 27
A14: Historias Should | B14: =COUNTIF('Historias de Usuario'!$J$5:$J$200,"Should") -> 15
A15: Historias Could | B15: =COUNTIF('Historias de Usuario'!$J$5:$J$200,"Could") -> 5
A16: Historia de referencia | B16: HU-04 | C16: Cerrar mi sesión, anclada en 2 puntos. Todas las demás se estimaron contra ella
A17: Requisitos funcionales | B17: =COUNTIF('Requisitos Funcionales'!$A$5:$A$100,"RF-*") -> 22 | C17: Catálogo incorporado al backlog en la v3.2
A18: Reglas de negocio definidas | B18: =COUNTIF('Reglas de Negocio'!$A$5:$A$100,"RN-*") -> 17
A19: Requisitos no funcionales | B19: =COUNTIF('Requisitos No Funcionales'!$A$5:$A$100,"RNF-*") -> 11
A20: Decisiones de arquitectura | B20: =COUNTIF('Decisiones (ADR)'!$A$5:$A$100,"ADR-*") -> 10 | C20: 10 decisiones, todas aceptadas. ADR-008 (stack tecnologico) se cerro el 11/09/2026 y ADR-010 (estilo arquitectonico) se registro en la v3.4.
A21: Necesidades trazadas | B21: =COUNTIF(Trazabilidad!$A$5:$A$100,"NEC-*") -> 12 | C21: Cada una cruzada con su stakeholder de origen
A22: Elementos fuera de alcance | B22: =COUNTIF('Fuera de alcance'!$B$5:$B$100,"Won?t*") -> 12 | C22: Documentar el Won't es parte de la evidencia. Cuenta las filas marcadas como Won't en la hoja Fuera de alcance.
A23: Historias por hacer | B23: =COUNTIF('Historias de Usuario'!$L$5:$L$200,"Por hacer") -> 47 | C23: Se actualiza a medida que avanza el desarrollo
A24: Historias terminadas | B24: =COUNTIF('Historias de Usuario'!$L$5:$L$200,"Hecho") -> 0
A25: Avance del proyecto (%) | B25: =IFERROR(SUMIF('Historias de Usuario'!$L$5:$L$200,"Hecho",'Historias de Usuario'!$K$5:$K$200)/B8,0) -> 0 | C25: Puntos terminados sobre puntos totales
A26: Historias técnicas | B26: =COUNTIF('Historias Tecnicas'!$A$5:$A$100,"HT-*") -> 8 | C26: Trabajo de soporte justificado por una decisión de arquitectura
A27: Casos de uso especificados | B27: =COUNTIF('Casos de Uso'!$A$5:$A$100,"CU-*") -> 6 | C27: Solo los flujos con bifurcaciones que la historia no alcanza a mostrar
A28: Supuestos abiertos | B28: =COUNTIF(Supuestos!$A$5:$A$100,"SUP-*") -> 1 | C28: Condiciones de las que depende parte del alcance

Sheet Actores
A1: Actores y necesidades
A2: Para quien se escribe el software. El libro distingue tres categorías: los 3 ROLES del sistema, que tienen credenciales y permisos; los 5 ACTORES, que son los roles más Persona nueva y Cliente ocasional, y son quienes inician una interacción en los diagramas; y los 6 INTERESADOS del proyecto, que agregan al equipo de desarrollo y al instructor, quienes no operan el sistema.
A4: Actor / Rol | B4: Tipo | C4: Descripción | D4: Que necesita lograr | E4: Por qué le importa | F4: Épicas relacionadas | G4: Stakeholder
A5: Persona nueva | B5: Actor sin rol (no autenticado) | C5: Usuario no autenticado | D5: Crear una cuenta e ingresar al sistema por primera vez, indicando si administra un parqueadero o si es cliente de uno. | E5: Es su único camino de entrada. Si el registro es confuso o le pide datos que no tiene a la mano, abandona. | F5: EP-01 | G5: -
A6: Administrador | B6: Rol del sistema (con credenciales) | C6: Propietario del parqueadero | D6: Configurar su parqueadero, registrar sus operarios, afiliar clientes, cobrar y ver como va el negocio. Solo sobre SU parqueadero. | E6: Es su fuente de ingresos. Un error de cálculo o un cliente en mora que se le pasa es plata que pierde ese mismo día. | F6: EP-01 a EP-08 | G6: STK-01
A7: Operario | B7: Rol del sistema (con credenciales) | C7: Vigilante o portero de turno, creado por el administrador | D7: Registrar entradas y salidas con rapidez durante su turno y ver la ocupación, sin acceso a tarifas, cartera ni reportes. | E7: Es quién está realmente en la caseta. Si el registro le toma más pasos que el cuaderno, no lo usa y el sistema fracasa. | F7: EP-01, EP-04 | G7: STK-02
A8: Cliente afiliado | B8: Rol del sistema (con credenciales) | C8: Usuario del parqueadero, vinculado a uno o más parqueaderos | D8: Consultar el historial de su vehículo, saber si está al día y revisar sus pagos registrados. | E8: Paga una mensualidad y hoy no tiene forma de verificar nada. Quedar en mora sin saberlo le puede costar el cupo. | F8: EP-01, EP-03, EP-06, EP-08 | G8: STK-03
A9: Cliente ocasional | B9: Actor sin rol (sin credenciales) | C9: Visitante de paso, sin cuenta ni credenciales. No confundir con el cliente afiliado de modalidad por horas, que si tiene cuenta. | D9: Entrar, parquear y salir pagando por el tiempo usado, y poder consultar su tiquete abierto con el código que le dieron a la entrada. | E9: Es la mayor parte de los movimientos de un parqueadero pequeño. El sistema debe atenderlo sin obligarlo a registrarse. | F9: EP-04 | G9: STK-04
A10: Equipo de desarrollo | B10: Interesado del proyecto, no actor del sistema | C10: Actor del proyecto, no del sistema | D10: Contar con requisitos estables y un alcance delimitado para construir, documentar y sustentar la plataforma. | E10: Un backlog abierto obliga a rehacer trabajo ya hecho y pone en riesgo el cronograma del Acta de Constitución. | F10: - | G10: STK-05
A11: Instructor del programa | B11: Interesado del proyecto, no actor del sistema | C11: Evaluador y asesor, no usuario del sistema | D11: Verificar que el proyecto aplique correctamente los conceptos de ingenieria de software. | E11: Aprueba o rechaza los entregables academicos. Le importa sobre todo la coherencia entre acta, stakeholders y requerimientos. | F11: - | G11: STK-06

Sheet Requisitos Funcionales
A1: Requisitos funcionales
A2: Que debe hacer el sistema, con la estructura actor + acción + objeto + condición. Cada requisito se deriva de un objetivo específico del Acta, del documento de Stakeholders o del Análisis de Seguridad, y se implementa a traves de las historias de usuario que lo desarrollan. Catálogo incorporado al backlog en la v3.2: antes vivía únicamente en el Anexo A de la plantilla P01.
A4: ID | B4: Nombre del requisito | C4: Descripción | D4: Origen | E4: Épica | F4: Historias que lo implementan
A5: RF-01 | B5: Registro de cuentas de administrador y cliente | C5: Permitir que una persona nueva cree su cuenta indicando si administra un parqueadero o si es cliente de uno. El registro del administrador crea también su parqueadero. | D5: Acta, Objetivo Específico 2 | E5: EP-01 | F5: HU-01, HU-02
A6: RF-02 | B6: Autenticación y direccionamiento por rol | C6: Validar credenciales, abrir sesión, fijar el parqueadero desde la sesión y dirigir a cada usuario al panel que le corresponde según su rol. | D6: Acta, Objetivo Específico 2 | E6: EP-01 | F6: HU-03, HU-04, HU-46
A7: RF-03 | B7: Gestión del perfil y recuperación de contraseña | C7: Permitir a cada usuario actualizar sus datos, cambiar su contraseña y recuperar el acceso de forma autonoma. | D7: Acta, Objetivo Específico 2 | E7: EP-01 | F7: HU-05, HU-06
A8: RF-04 | B8: Administración de cuentas de operario | C8: Permitir al administrador crear, habilitar y desactivar cuentas de operario limitadas a su parqueadero y con permisos restringidos. | D8: Acta, Objetivo General y Específico 2 | E8: EP-01 | F8: HU-38, HU-39
A9: RF-05 | B9: Gestión del inventario de celdas | C9: Registrar las celdas del parqueadero con código único y tipo de vehículo permitido. | D9: Acta, Objetivo Específico 4 | E9: EP-02 | F9: HU-07, HU-08
A10: RF-06 | B10: Visualización de la ocupación en tiempo real | C10: Mostrar el estado actual de cada celda y la lista de vehículos presentes en el parqueadero. | D10: Acta, Objetivo Específico 4 | E10: EP-02, EP-04 | F10: HU-23, HU-33
A11: RF-07 | B11: Gestión y versionado de tarifas | C11: Definir los valores por hora, por día y por mensualidad, versionarlos con fecha de vigencia y consultar su histórico. | D11: Acta, Objetivo Específico 5 | E11: EP-02 | F11: HU-09, HU-11
A12: RF-08 | B12: Administración de los datos del parqueadero | C12: Permitir corregir o actualizar el nombre, la dirección y la ubicación del parqueadero. | D12: Acta, Objetivo Específico 1 | E12: EP-02 | F12: HU-10
A13: RF-09 | B13: Afiliación de clientes y vehículos | C13: Registrar clientes con sus vehículos, consultarlos, asociarles vehículos adicionales, cerrar vínculos por cambio de dueño y desactivar afiliaciones. | D13: Acta, Objetivo Específico 1 | E13: EP-03 | F13: HU-12a, HU-14, HU-15, HU-16, HU-17, HU-18
A14: RF-10 | B14: Vinculación del cliente mediante código | C14: Emitir, entregar y validar el código que permite al cliente asociar su cuenta a su vehículo y a un parqueadero. | D14: Acta, Objetivo Específico 1 + ADR-002 | E14: EP-03 | F14: HU-12b, HU-13
A15: RF-11 | B15: Registro de entrada de vehículos | C15: Registrar el ingreso de vehículos afiliados y ocasionales asignando una celda libre compatible y congelando la tarifa vigente. | D15: Acta, Objetivo Específico 3 | E15: EP-04 | F15: HU-19, HU-20
... A26: RF-22 | B26: Registro de movimientos mediante lector de código QR | C26: Permitir que un dispositivo lector envíe a la API el código QR leido en la entrada o en la salida, para que el operario confirme la placa y cierre el registro. El registro manual permanece disponible como vía alterna cuando el lector no esta operativo. | D26: Decisión del equipo 28/08/2026 + ADR-009 | E26: EP-04 | F26: HU-43, HU-44, HU-45
A28: Los 20 primeros requisitos se tomaron integros del Anexo A de la plantilla P01. RF-21 y RF-22 son nuevos en la v3.2 y recogen la decisión de registrar los movimientos con lector de código QR (ADR-009).

Sheet Epicas
A1: Épicas
A2: Agrupadas por capacidad del sistema, no por pantalla. Las tres ultimas columnas se calculan solas desde la hoja Historias de Usuario.
A4: ID | B4: Titulo de la épica | C4: Descripción | D4: Objetivo de negocio / valor | E4: N historias | F4: Puntos | G4: % del total
A5: EP-01 | B5: Identidad y acceso | C5: Creación de cuentas, autenticación con tres roles, creación de operarios, recuperación de contraseña y gestión del perfil propio. Es la única puerta de entrada al sistema. | D5: Que cada persona entre de forma segura y que el sistema sepa automáticamente que información mostrarle según su rol. | E5: =COUNTIF('Historias de Usuario'!$B$5:$B$200,$A5) -> 9 | F5: =SUMIF('Historias de Usuario'!$B$5:$B$200,$A5,'Historias de Usuario'!$K$5:$K$200) -> 30 | G5: =IFERROR(F5/SUM($F$5:$F$12),0) -> 0.16042781
A6: EP-02 | B6: Configuración del parqueadero | C6: Datos del parqueadero, inventario de celdas identificadas y tarifas versionadas. Es lo que el administrador deja listo una vez para que la operación diaria funcione sola. | D6: Que el administrador configure su negocio una sola vez y el sistema calcule todo lo demás sin intervención manual. | E6: =COUNTIF('Historias de Usuario'!$B$5:$B$200,$A6) -> 5 | F6: =SUMIF('Historias de Usuario'!$B$5:$B$200,$A6,'Historias de Usuario'!$K$5:$K$200) -> 21 | G6: =IFERROR(F6/SUM($F$5:$F$12),0) -> 0.11229947
A7: EP-03 | B7: Afiliación de clientes y vehículos | C7: Vínculo entre una persona, un vehículo y un parqueadero. Incluye el registro que hace el administrador, el código de vinculación y el cierre del vínculo por cambio de dueño. | D7: Que cada cliente quede correctamente asociado a su parqueadero y a su vehículo, sin duplicados y sin que nadie pueda reclamar información ajena. | E7: =COUNTIF('Historias de Usuario'!$B$5:$B$200,$A7) -> 10 | F7: =SUMIF('Historias de Usuario'!$B$5:$B$200,$A7,'Historias de Usuario'!$K$5:$K$200) -> 36 | G7: =IFERROR(F7/SUM($F$5:$F$12),0) -> 0.19251337
A8: EP-04 | B8: Operación diaria de entradas y salidas | C8: El nucleo del sistema: registrar quien entra, quien sale, cuanto tiempo estuvo y cuanto debe pagar. Cubre al cliente afiliado y al ocasional, y es la épica que más usa el operario. | D8: Que el control de acceso y el cobro dejen de hacerse a mano, eliminando errores de cálculo y perdida de ingresos. | E8: =COUNTIF('Historias de Usuario'!$B$5:$B$200,$A8) -> 9 | F8: =SUMIF('Historias de Usuario'!$B$5:$B$200,$A8,'Historias de Usuario'!$K$5:$K$200) -> 42 | G8: =IFERROR(F8/SUM($F$5:$F$12),0) -> 0.22459893
A9: EP-05 | B9: Cartera y pagos de mensualidades | C9: Estado de cuenta de los clientes mensuales, registro de pagos, detección de mora y carta de cobro. | D9: Que el administrador sepa en todo momento quien le debe y cuanto, sin depender de cuadernos. | E9: =COUNTIF('Historias de Usuario'!$B$5:$B$200,$A9) -> 5 | F9: =SUMIF('Historias de Usuario'!$B$5:$B$200,$A9,'Historias de Usuario'!$K$5:$K$200) -> 23 | G9: =IFERROR(F9/SUM($F$5:$F$12),0) -> 0.12299465
A10: EP-06 | B10: Portal del cliente | C10: Vista propia del cliente sobre su vehículo: historial de movimientos, estado de su mensualidad y sus pagos registrados. | D10: Que el cliente consulte su propia información sin tener que preguntarle al administrador, generando transparencia. | E10: =COUNTIF('Historias de Usuario'!$B$5:$B$200,$A10) -> 3 | F10: =SUMIF('Historias de Usuario'!$B$5:$B$200,$A10,'Historias de Usuario'!$K$5:$K$200) -> 9 | G10: =IFERROR(F10/SUM($F$5:$F$12),0) -> 0.048128342
A11: EP-07 | B11: Reportes y analitica | C11: Informes de ingresos, ocupación y movimientos por rango de fechas, exportables. | D11: Que el administrador entienda como va su negocio con datos y no con percepción. | E11: =COUNTIF('Historias de Usuario'!$B$5:$B$200,$A11) -> 3 | F11: =SUMIF('Historias de Usuario'!$B$5:$B$200,$A11,'Historias de Usuario'!$K$5:$K$200) -> 13 | G11: =IFERROR(F11/SUM($F$5:$F$12),0) -> 0.069518717
A12: EP-08 | B12: Seguridad, auditoría y datos personales | C12: Capacidades transversales: consentimiento de tratamiento de datos, bitácora de auditoría de operaciones sensibles y ejercicio del derecho de supresión. | D12: Que el sistema sea defendible legal y técnicamente, y que toda operación sobre dinero o datos personales quede rastreada. | E12: =COUNTIF('Historias de Usuario'!$B$5:$B$200,$A12) -> 3 | F12: =SUMIF('Historias de Usuario'!$B$5:$B$200,$A12,'Historias de Usuario'!$K$5:$K$200) -> 13 | G12: =IFERROR(F12/SUM($F$5:$F$12),0) -> 0.069518717
A13: TOTAL | E13: =SUM(E5:E12) -> 47 | F13: =SUM(F5:F12) -> 187 | G13: =SUM(G5:G12) -> 1

Sheet Historias de Usuario
A1: Historias de usuario
A2: Una fila por historia, con su escenario de error. Las columnas Épica, MoSCoW, Puntos y Estado son listas desplegables. La columna Stakeholder cruza cada historia con el documento de Stakeholders v2.
A3: APAR-CAR v3.2 - Ficha 3229209. Historia de referencia: HU-04 (Cerrar mi sesión), anclada en 2 puntos.
A4: ID | B4: Épica | C4: Rol principal | D4: Titulo | E4: Como (rol) | F4: Quiero (acción) | G4: Para (beneficio) | H4: Criterios de aceptación (Dado / Cuando / Entonces) | I4: Escenario de error (Dado / Cuando / Entonces) | J4: MoSCoW | K4: Puntos | L4: Estado | M4: Dependencias | N4: Trazabilidad (RN / RNF / ADR) | O4: Stakeholder
A5: HU-01 | B5: EP-01 | C5: Persona nueva | D5: Registrarme como administrador con mi parqueadero | E5: persona nueva que administra un parqueadero | F5: crear mi cuenta indicando mis datos personales y los datos de mi parqueadero | G5: que el sistema cree mi parqueadero y me deje administrarlo desde el primer ingreso | H5: Dado que soy una persona nueva y elijo el tipo de cuenta administrador, cuando diligencio nombres, apellidos, correo, teléfono, contraseña y los datos de mi parqueadero (nombre, dirección, ubicación) y acepto la política de tratamiento de datos, entonces el sistema crea mi usuario, crea el parqueadero, me afilia a el con rol administrador y me permite iniciar sesión. | I5: Dado que el correo que ingreso ya está registrado, cuando intento crear la cuenta, entonces el sistema no la crea y me indica que ese correo ya existe, ofreciendome recuperar la contraseña. | J5: Must | K5: 5 | L5: Por hacer | M5: HU-35 | N5: RN-08, RN-09, RNF-01, RNF-03, RNF-05, ADR-001 | O5: -
A6: HU-02 | B6: EP-01 | C6: Persona nueva | D6: Registrarme como cliente | E6: persona nueva que usa un parqueadero | F6: crear mi cuenta con mis datos personales | G6: poder después vincularme a mi vehículo y consultar mi información | H6: Dado que soy una persona nueva y elijo el tipo de cuenta cliente, cuando diligencio mis datos y acepto la política de tratamiento de datos, entonces el sistema crea mi usuario sin afiliación y me lleva a la pantalla de vinculación de vehículo. | I6: Dado que dejo campos obligatorios vacíos o el correo tiene formato invalido, cuando intento registrarme, entonces el sistema señala cada campo con error y no crea la cuenta. | J6: Must | K6: 3 | L6: Por hacer | M6: HU-35 | N6: RN-08, RN-09, RNF-03, RNF-05 | O6: -
A7: HU-03 | B7: EP-01 | C7: Administrador / Operario / Cliente afiliado | D7: Iniciar sesión y ser dirigido según mi rol | E7: usuario registrado | F7: ingresar con mi correo y contraseña | G7: entrar directamente a la parte del sistema que me corresponde | H7: Dado que ingreso credenciales correctas, cuando presiono Iniciar sesión, entonces el sistema abre mi sesión y me dirige al panel que corresponde a mi rol: administrador, operario o cliente. El identificador del parqueadero queda fijado desde la sesión y no vuelve a pedirse. | I7: Dado que ingreso una contraseña incorrecta, cuando intento entrar, entonces el sistema muestra un mensaje genérico de credenciales invalidas sin revelar cual de los dos datos fallo, y bloquea el acceso temporalmente tras 5 intentos fallidos. | J7: Must | K7: 3 | L7: Por hacer | M7: HU-01, HU-02 | N7: RN-09, RNF-01, RNF-02, RNF-03, RNF-04, ADR-005 | O7: STK-01, STK-02, STK-03
A8: HU-04 | B8: EP-01 | C8: Administrador / Operario / Cliente afiliado | D8: Cerrar mi sesión | E8: usuario autenticado | F8: cerrar mi sesión de forma explicita | G8: evitar que otra persona use mi cuenta en un equipo compartido | H8: Dado que tengo una sesión abierta, cuando presiono Cerrar sesión, entonces el sistema invalida la sesión y me devuelve a la pantalla de ingreso. | I8: Dado que mi sesión ya fue invalidada, cuando intento volver a una pantalla interna con el boton atrás del navegador, entonces el sistema me redirige a la pantalla de ingreso y no muestra ningún dato. | J8: Must | K8: 2 | L8: Por hacer | M8: HU-03 | N8: RNF-02 | O8: STK-01, STK-02, STK-03
A9: HU-05 | B9: EP-01 | C9: Administrador / Operario / Cliente afiliado | D9: Recuperar mi contraseña | E9: usuario registrado que olvido su contraseña | F9: restablecerla mediante un enlace enviado a mi correo | G9: recuperar el acceso sin depender de nadie | H9: Dado que solicito recuperar mi contraseña con un correo registrado, cuando confirmo, entonces el sistema envía un enlace de un solo uso con vencimiento de 1 hora y permite definir una contraseña nueva. | I9: Dado que el enlace ya fue usado o ya venció, cuando intento abrirlo, entonces el sistema lo rechaza y me ofrece solicitar uno nuevo. | J9: Should | K9: 3 | L9: Por hacer | M9: HU-03 | N9: RN-09, RNF-01 | O9: STK-01, STK-02, STK-03
A10: HU-06 | B10: EP-01 | C10: Administrador / Operario / Cliente afiliado | D10: Actualizar mis datos de perfil | E10: usuario autenticado | F10: modificar mi teléfono, mi nombre y mi contraseña | G10: mantener mi información al día sin pedirle ayuda a nadie | H10: Dado que estoy autenticado, cuando modifico mis datos de perfil y guardo, entonces el sistema los actualiza y me confirma el cambio. | I10: Dado que intento cambiar mi contraseña, cuando no ingreso correctamente la contraseña actual, entonces el sistema rechaza el cambio y no modifica nada. | J10: Should | K10: 3 | L10: Por hacer | M10: HU-03 | N10: RNF-01, RNF-05 | O10: STK-01, STK-02, STK-03
A11: HU-07 | B11: EP-02 | C11: Administrador | D11: Registrar las celdas de mi parqueadero | E11: administrador | F11: dar de alta las celdas de mi parqueadero con un código y un tipo de vehículo permitido | G11: tener un inventario real de mi capacidad y no solo un número | H11: Dado que soy administrador, cuando registro una celda indicando su código (por ejemplo A-01) y el tipo permitido (carro, moto o mixta), entonces el sistema la guarda con estado Libre y la suma a mi capacidad total. El sistema permite también crear celdas en lote indicando un prefijo y una cantidad. | I11: Dado que intento registrar una celda con un código que ya existe en mi parqueadero, cuando guardo, entonces el sistema rechaza el registro e indica que ese código ya está en uso. | J11: Must | K11: 5 | L11: Por hacer | M11: HU-01 | N11: RN-01, ADR-003 | O11: STK-01
A12: HU-08 | B12: EP-02 | C12: Administrador / Operario | D12: Ver la ocupación de mis celdas en tiempo real | E12: administrador | F12: ver un tablero con cuales celdas están ocupadas y cuales libres en este momento | G12: saber de inmediato si tengo cupo para un vehículo que esta llegando | H12: Dado que tengo celdas registradas, cuando entro al tablero de ocupación, entonces veo cada celda con su estado actual, la placa que la ocupa cuando aplica, la hora de entrada, y los totales de libres y ocupadas. | I12: Dado que aún no he registrado ninguna celda, cuando entro al tablero, entonces el sistema me muestra un mensaje guiándome a registrarlas primero, con un enlace directo a esa pantalla. | J12: Must | K12: 5 | L12: Por hacer | M12: HU-07 | N12: RN-01, RNF-06 | O12: STK-01
A13: HU-09 | B13: EP-02 | C13: Administrador | D13: Definir y versionar mis tarifas | E13: administrador | F13: establecer el valor por hora, por día y por mensualidad, y cambiarlos cuando lo necesite | G13: que el sistema cobre siempre con la tarifa correcta sin que yo calcule nada | H13: Dado que soy administrador, cuando registro una tarifa indicando modalidad, valor y fecha de vigencia, entonces el sistema la guarda como una versión nueva sin borrar la anterior y la aplica a los movimientos que inicien desde esa fecha. Los vehículos que ya están adentro conservan la tarifa vigente al momento de su entrada. | I13: Dado que intento guardar una tarifa vacía, en cero o negativa, cuando confirmo, entonces el sistema no guarda y señala el campo con el error. | J13: Must | K13: 5 | L13: Por hacer | M13: HU-01 | N13: RN-02, RN-03, ADR-004 | O13: STK-01
A14: HU-10 | B14: EP-02 | C14: Administrador | D14: Editar los datos de mi parqueadero | E14: administrador | F14: actualizar el nombre, la dirección y la ubicación de mi parqueadero | G14: corregir errores del registro inicial o reflejar un cambio real | H14: Dado que soy administrador, cuando modifico los datos de mi parqueadero y guardo, entonces el sistema los actualiza y quedan reflejados en los documentos que se generen desde ese momento. | I14: Dado que dejo el nombre o la dirección en blanco, cuando intento guardar, entonces el sistema rechaza el cambio y conserva los datos anteriores. | J14: Should | K14: 3 | L14: Por hacer | M14: HU-01 | N14: RNF-08 | O14: STK-01
A15: HU-11 | B15: EP-02 | C15: Administrador | D15: Consultar el histórico de mis tarifas | E15: administrador | F15: ver todas las versiones de tarifa que he tenido con sus fechas de vigencia | G15: poder explicarle a un cliente por qué se le cobro un valor determinado | H15: Dado que he cambiado mis tarifas al menos una vez, cuando consulto el histórico, entonces veo cada versión con su modalidad, valor, fecha de vigencia y fecha de reemplazo. | I15: Dado que nunca he modificado mis tarifas, cuando consulto el histórico, entonces el sistema muestra únicamente la versión inicial e indica que no hay cambios posteriores. | J15: Could | K15: 3 | L15: Por hacer | M15: HU-09 | N15: RN-02, RNF-07 | O15: STK-01
A16: HU-12a | B16: EP-03 | C16: Administrador | D16: Registrar un cliente y su vehículo | E16: administrador | F16: dar de alta a un cliente con sus datos personales, la placa de su vehículo y su modalidad | G16: tener en el sistema quién usa mi parqueadero y en que condiciones | H16: Dado que soy administrador, cuando registro un cliente con sus datos de contacto, la placa de su vehículo y la modalidad (mensual o por horas), entonces el sistema normaliza la placa, crea la afiliación en estado Pendiente de vinculación y la asocia a mi parqueadero. La modalidad por horas identifica a un cliente afiliado que paga por tiempo; no debe confundirse con el cliente ocasional, que no tiene cuenta ni afiliación. | I16: Dado que la placa que ingreso ya está activa y vinculada a otro cliente en mi parqueadero, cuando intento guardar, entonces el sistema rechaza el registro e indica a que afiliación pertenece esa placa, sin revelar datos personales del otro cliente. | J16: Must | K16: 5 | L16: Por hacer | M16: HU-01 | N16: RN-04, RN-06, RNF-03, ADR-002 | O16: STK-01
... A51: HU-47 | B51: EP-05 | C51: Administrador | D51: Anular un pago registrado por error indicando el motivo | E51: administrador del parqueadero | F51: anular un pago que registre por error dejando escrito el motivo, y registrar el pago correcto aparte | G51: poder corregir un error de digitacion sin borrar el historial de dinero del cliente ni perder la cuenta de su cartera | H51: Dado un pago ya registrado, cuando lo anulo escribiendo el motivo, entonces el pago queda marcado como anulado sin borrarse (RN-13), se recalcula la fecha de vencimiento y el estado de cartera del cliente (RN-11, RN-12), y la anulacion queda en la bitacora con usuario, fecha, hora y motivo (RNF-07). / Dado un pago anulado, cuando consulto el historial de pagos del cliente, entonces aparece como anulado y no cuenta para el periodo vigente. / Dado que el valor registrado era incorrecto, cuando quiero corregirlo, entonces anulo el pago y registro uno nuevo, porque un pago no se edita ni se elimina. | I51: Dado que intento anular un pago sin escribir el motivo, cuando confirmo la operacion, entonces el sistema la rechaza, el pago permanece vigente y no se modifica ningun estado de cartera. | J51: Should | K51: 5 | L51: Por hacer | M51: HU-24 | N51: RN-11, RN-12, RN-13, RNF-07, RF-14, ADR-007 | O51: STK-01

Sheet Reglas de Negocio
A1: Reglas de negocio
A2: Condiciones que el sistema debe cumplir siempre, independientes de la pantalla. Se separan de las historias para no repetirlas en cada criterio de aceptación.
A4: ID | B4: Nombre | C4: Enunciado de la regla | D4: Historias que la aplican
A5: RN-01 | B5: Capacidad y celdas | C5: Cada celda pertenece a un único parqueadero, tiene un código único dentro de el y un tipo permitido (carro, moto o mixta). Una celda solo puede estar en estado Libre u Ocupada, y solo puede alojar un vehículo a la vez. | D5: HU-07, HU-08, HU-19, HU-20, HU-23, HU-33
A6: RN-02 | B6: Versionado de tarifas | C6: Una tarifa nunca se edita ni se borra: cada cambio crea una versión nueva con su fecha de vigencia. La versión anterior queda cerrada con fecha de reemplazo y permanece consultable. | D6: HU-09, HU-11, HU-21
A7: RN-03 | B7: Congelamiento de tarifa | C7: El movimiento guarda la referencia a la versión de tarifa vigente en el instante de la ENTRADA. El cobro de la salida se calcula siempre con esa versión, aunque la tarifa haya cambiado mientras el vehículo estuvo adentro. | D7: HU-09, HU-19, HU-20, HU-21
A8: RN-04 | B8: Formato y normalización de placa | C8: Antes de comparar o guardar, la placa se normaliza a mayúsculas y se le retiran espacios y guiones. Se valida contra el formato colombiano: AAA000 para automovil y AAA00A para motocicleta. La placa es única entre los vehículos ACTIVOS de un mismo parqueadero, no a nivel global del sistema. | D8: HU-12a, HU-13, HU-15, HU-19, HU-20
A9: RN-05 | B9: Código de vinculación | C9: El código de vinculación es alfanumérico de 6 caracteres, de un solo uso y vence a los 7 días calendario desde su emisión. Se invalida al usarse, al vencer, al generarse uno nuevo para la misma afiliación o tras tres intentos fallidos de vinculación. Se muestra una sola vez en pantalla y su emisión queda en la bitácora. | D9: HU-12b, HU-13, HU-17
A10: RN-06 | B10: La placa identifica, no autentica | C10: La placa por si sola NUNCA autoriza acceso a información. Toda vinculación exige placa más código emitido por el administrador. Ante un intento fallido el sistema no revela si la placa existe. | D10: HU-12a, HU-12b, HU-13, HU-15, HU-40
A11: RN-07 | B11: Vigencia del vínculo vehículo-cliente | C11: La relación entre un vehículo y una afiliación tiene fecha de inicio y fecha de fin. Al cambiar de dueño el vínculo se cierra, nunca se borra ni se reasigna. Cada movimiento pertenece al vínculo vigente en su fecha, de modo que el dueño anterior conserva su historial y el nuevo no lo ve. | D11: HU-16, HU-18, HU-28
A12: RN-08 | B12: Consentimiento de datos personales | C12: Ningún dato personal se almacena sin base de autorización. Cuando el titular se registra por si mismo, la autorización es explicita y no premarcada, y se guarda la constancia con fecha y versión del texto aceptado. Cuando los datos los captura un tercero dentro del sistema (el administrador al registrar un cliente en HU-12a o al crear un operario en HU-38), el responsable declara contar con la autorización del titular y el sistema exige al titular aceptar la política en su primer ingreso, antes de habilitarle cualquier función. Del cliente ocasional solo se registra la placa, que se trata como dato personal para efectos de supresión. La política debe informar por adelantado que, ante una solicitud de supresión, los registros de dinero se conservan anonimizados por trazabilidad contable y que la supresión no procede mientras exista un deber contractual vigente. | D12: HU-01, HU-02, HU-12a, HU-13, HU-20, HU-35, HU-37, HU-38
A13: RN-09 | B13: Credenciales | C13: Las contraseñas se almacenan únicamente como hash con sal. Nunca se guardan ni se transmiten en texto plano, y nunca se muestran ni se envían por correo. El mensaje de error de ingreso es genérico y no revela si el correo existe. | D13: HU-01, HU-02, HU-03, HU-05, HU-38, HU-46
A14: RN-10 | B14: Unicidad de presencia | C14: Una misma placa no puede tener dos movimientos abiertos simultáneos dentro del mismo parqueadero. Un movimiento se considera abierto mientras no tenga hora de salida. | D14: HU-19, HU-20, HU-21, HU-23
A15: RN-11 | B15: Ciclo de la mensualidad | C15: El período mensual es RODANTE. El primer pago de una afiliación inicia el período en su propia fecha y vence 30 días calendario después. A partir de ahí, un pago registrado antes del vencimiento encadena el período nuevo desde la fecha de vencimiento anterior y no desde la fecha de pago, de modo que el cliente no pierde los días que le quedaban. Un pago registrado después del vencimiento inicia un período nuevo en su propia fecha. Decisión cerrada en ADR-004; no hay prorrateo. | D15: HU-21, HU-24, HU-25, HU-29, HU-47
... A21: RN-17 | B21: Ciclo de vida del código QR del vehículo afiliado | C21: Cada vehículo afiliado tiene un único código QR activo a la vez. Se emite al registrar el vehículo y se entrega al titular, que lo conserva y lo porta consigo. El administrador puede revocarlo en cualquier momento por perdida, deterioro o cierre del vínculo vehículo-cliente; al revocarlo se puede emitir uno nuevo, y el anterior queda invalido de forma inmediata. La emisión, la entrega y la revocación quedan en la bitácora con usuario, fecha y motivo. Al cerrarse el vínculo por cambio de dueño según RN-07, el código se revoca automáticamente. | D21: HU-41, HU-42, HU-16, HU-18

Sheet Requisitos No Funcionales
A1: Requisitos no funcionales
A2: Cada uno trae su criterio de verificación: un RNF que no se puede verificar no es un requisito, es un deseo. La ultima columna cruza cada RNF con el riesgo que mitiga del documento Análisis de Seguridad en la Implantación de Software.
A4: ID | B4: Categoría | C4: Requisito | D4: Como se verifica | E4: Prioridad | F4: Relacionado con | G4: Riesgo que mitiga (Análisis de Seguridad)
A5: RNF-01 | B5: Seguridad - autenticación | C5: Contraseñas almacenadas como hash con sal mediante un algoritmo de derivación de clave reconocido. La sesión expira tras 30 minutos de inactividad. Tras 5 intentos fallidos consecutivos la cuenta queda bloqueada durante 15 minutos. El operario debe cambiar su contraseña inicial en el primer ingreso. | D5: Un intento de fuerza bruta de 100 combinaciones sobre una cuenta debe quedar bloqueado y registrado en la bitácora. | E5: Alta | F5: HU-01, HU-03, HU-05, HU-06, HU-38, HU-46 | G5: R2 - Robo de credenciales de usuario
A6: RNF-02 | B6: Seguridad - aislamiento entre parqueaderos | C6: El identificador del parqueadero se deriva SIEMPRE de la sesión autenticada, nunca de un parametro enviado por el cliente. Ninguna consulta puede devolver datos de un parqueadero distinto al de la sesión. | D6: El administrador del parqueadero A solicita un recurso del parqueadero B alterando el identificador en la petición y el sistema responde acceso denegado. | E6: Crítica | F6: Transversal a EP-01 a EP-08 | G6: R4 - Escalamiento de privilegios entre roles
A7: RNF-03 | B7: Seguridad - autorización por rol | C7: Cada operación valida rol y pertenencia EN EL SERVIDOR, no solo ocultando opciones en la interfaz. Matriz de permisos: el administrador accede a todo su parqueadero; el operario solo a ocupación, entrada, salida y vehículos adentro; el cliente solo a sus propios datos. Un cliente no puede acceder a datos de otro cliente ni a funciones de administrador, y un operario no puede acceder a tarifas, cartera, clientes, reportes ni bitácora. | D7: Tres pruebas: un cliente solicita el historial de otro cliente y recibe acceso denegado; un operario solicita el reporte de ingresos y recibe acceso denegado; ambos intentos quedan en la bitácora. | E7: Crítica | F7: HU-13, HU-19, HU-28, HU-30, HU-39, Transversal | G7: R4 - Escalamiento de privilegios entre roles
A8: RNF-04 | B8: Seguridad - transporte | C8: Toda comunicación sobre HTTPS. Ninguna credencial, código de vinculación, código de tiquete ni dato personal viaja en la URL ni queda en los registros del servidor. | D8: Inspección de tráfico y de logs sin encontrar credenciales, códigos ni datos personales en claro. | E8: Alta | F8: Transversal, HU-40 | G8: R2 - Robo de credenciales / R5 - Filtración de documentación
A9: RNF-05 | B9: Protección de datos personales | C9: Se recolecta el mínimo dato necesario. Del cliente ocasional no se captura ningún dato de contacto ni documento de identidad: solo la placa y un código de tiquete. La placa se trata como dato personal para efectos de supresión y nunca se muestra completa en pantallas públicas. Política de tratamiento publicada y aceptada de forma explicita. La supresión se atiende por anonimización, conservando los registros de dinero sin titular identificable (Ley 1581 de 2012 y Decreto 1377 de 2013, compilado en el Decreto 1074 de 2015). | D9: Un registro de cliente ocasional se completa sin capturar nombre, documento, teléfono ni correo; la consulta pública de HU-40 nunca devuelve la placa completa; una solicitud de supresión deja el registro de pago intacto y sin titular identificable. | E9: Alta | F9: HU-20, HU-27, HU-35, HU-37, HU-40, HU-43 | G9: R1 - Acceso no autorizado a la base de datos / R5
A10: RNF-06 | B10: Desempeño | C10: Las pantallas operativas de uso frecuente (ocupación, entrada, salida, vehículos adentro y listado de clientes) responden en menos de 2 segundos sobre un conjunto de datos de referencia de 60 celdas, 200 clientes afiliados y 12 meses de movimientos. | D10: Prueba de carga sobre el conjunto de datos de referencia midiendo el percentil 95 del tiempo de respuesta de las cinco pantallas indicadas. | E10: Media | F10: HU-08, HU-14, HU-23, HU-32, HU-33, HU-39 | G10: -
A11: RNF-07 | B11: Auditoría y trazabilidad | C11: Toda operación sobre dinero, tarifas, vinculaciones, cuentas de operario y datos personales queda en una bitácora solo anexable (se escribe y se consulta, pero ningún registro se modifica ni se elimina) con usuario, fecha y hora. Las operaciones que corrigen o revierten un hecho ya registrado (anulaciones y correcciones de movimiento) exigen además un motivo escrito. Ningún rol puede modificar ni eliminar la bitácora. | D11: Ejecutar una anulación y verificar que el evento aparece en la bitácora y que ningún rol logra modificarlo. | E11: Alta | F11: HU-11, HU-16, HU-17, HU-22, HU-26, HU-34, HU-36, HU-37, HU-38, HU-39, HU-46, HU-47 | G11: R1 - Acceso no autorizado / R4 - Escalamiento de privilegios
A12: RNF-08 | B12: Usabilidad | C12: Ni el administrador ni el operario objetivo son personas con formación técnica. Registrar una entrada y registrar una salida deben completarse en no más de cinco pasos cada una y sin capacitación previa. | D12: Prueba con 3 usuarios sin formación técnica: al menos 2 completan ambas tareas sin ayuda, dentro del limite de cinco pasos y sin errores que impidan terminar. | E12: Alta | F12: HU-10, HU-19, HU-20, HU-21, HU-39 | G12: -
A13: RNF-09 | B13: Disponibilidad y respaldo | C13: Respaldo automático diario de la base de datos con retención de 30 días y procedimiento de restauración probado al menos una vez antes de la entrega. | D13: Ejecutar una restauración completa desde un respaldo y verificar la integridad de los datos. | E13: Media | F13: Transversal | G13: R1 - Pérdida o alteración de la base de datos
A14: RNF-10 | B14: Seguridad - gestión del código fuente | C14: El repositorio permanece privado durante todo el proyecto. Ninguna credencial, clave de conexión ni dato real de prueba se versiona: la configuración sensible se maneja por variables de entorno y el archivo de ejemplo se pública sin valores. Se revisa el historial antes de cada entrega. | D14: Revisión del repositorio y de su historial de commits sin encontrar credenciales ni cadenas de conexión; verificación de que la visibilidad es privada. | E14: Media | F14: Transversal al proyecto | G14: R3 - Filtración del código fuente
A15: RNF-11 | B15: Seguridad - dispositivo lector | C15: El dispositivo lector se autentica ante la API con una clave propia de dispositivo, revocable desde el sistema y distinta de las credenciales de cualquier persona. Envía únicamente el código leido y el identificador del punto de lectura, siempre sobre HTTPS y en el cuerpo de la petición, nunca en la URL. Un lector no autenticado, revocado o desconocido es rechazado y el intento queda en la bitácora. La indisponibilidad del lector no bloquea la operación: el registro manual permanece habilitado en todo momento. | D15: Se envía una lectura desde un dispositivo sin clave valida y el sistema responde acceso denegado dejando el intento en la bitácora; se desconecta el lector y el operario completa una entrada y una salida por la vía manual. | E15: Alta | F15: HU-43, HU-44, HU-45, RN-16 | G15: R2 - Robo de credenciales
A16: Nota: el ultimo requisito es nuevo en la v3.0. El riesgo R3 del Análisis de Seguridad (filtración del código fuente) no estaba cubierto por ningún requisito verificable.

Sheet INVEST
A1: Checklist INVEST por historia
A2: Independiente / Negociable / Valiosa / Estimable / Small / Testeable. El criterio I se evalua como ENTREGABLE de forma independiente, no como construible en cualquier orden: se marca Revisar únicamente cuando la historia no aporta valor por si sola sin otra. Una observación escrita vale más que un Si sin sustento.
A4: ID | B4: Titulo | C4: I | D4: N | E4: V | F4: E | G4: S | H4: T | I4: Observación
A5: HU-01 | B5: Registrarme como administrador con mi parqueadero | C5: Si | D5: Si | E5: Si | F5: Si | G5: Si | H5: Si
A6: HU-02 | B6: Registrarme como cliente | C6: Si | D6: Si | E6: Si | F6: Si | G6: Si | H6: Si
A7: HU-03 | B7: Iniciar sesión y ser dirigido según mi rol | C7: Si | D7: Si | E7: Si | F7: Si | G7: Si | H7: Si
A8: HU-04 | B8: Cerrar mi sesión | C8: Si | D8: Si | E8: Si | F8: Si | G8: Si | H8: Si
A9: HU-05 | B9: Recuperar mi contraseña | C9: Si | D9: Si | E9: Si | F9: Si | G9: Si | H9: Si
A10: HU-06 | B10: Actualizar mis datos de perfil | C10: Si | D10: Si | E10: Si | F10: Si | G10: Si | H10: Si
A11: HU-07 | B11: Registrar las celdas de mi parqueadero | C11: Si | D11: Si | E11: Si | F11: Si | G11: Si | H11: Si
A12: HU-08 | B12: Ver la ocupación de mis celdas en tiempo real | C12: Si | D12: Si | E12: Si | F12: Si | G12: Si | H12: Si
A13: HU-09 | B13: Definir y versionar mis tarifas | C13: Si | D13: Si | E13: Si | F13: Si | G13: Si | H13: Si
A14: HU-10 | B14: Editar los datos de mi parqueadero | C14: Si | D14: Si | E14: Si | F14: Si | G14: Si | H14: Si
A15: HU-11 | B15: Consultar el histórico de mis tarifas | C15: Si | D15: Si | E15: Si | F15: Si | G15: Si | H15: Si
A16: HU-12a | B16: Registrar un cliente y su vehículo | C16: Si | D16: Si | E16: Si | F16: Si | G16: Si | H16: Si | I16: Resuelto en la v3.0: la antigua HU-12 de 8 puntos se dividió. Esta mitad entrega valor por si sola porque el administrador ya tiene su lista de clientes aunque el código todavía no exista.
A17: HU-12b | B17: Generar el código de vinculación de un cliente | C17: Revisar | D17: Si | E17: Si | F17: Si | G17: Si | H17: Si | I17: Depende de HU-12a en el orden de construcción, pero se entrega y se prueba de forma independiente.
A18: HU-13 | B18: Vincular mi cuenta a mi vehículo con placa y código | C18: Si | D18: Si | E18: Si | F18: Si | G18: Si | H18: Si
A19: HU-14 | B19: Ver y filtrar la lista de mis clientes afiliados | C19: Si | D19: Si | E19: Si | F19: Si | G19: Si | H19: Si
A20: HU-15 | B20: Asociar un segundo vehículo a un cliente ya afiliado | C20: Si | D20: Si | E20: Si | F20: Si | G20: Si | H20: Si
A21: HU-16 | B21: Cerrar la vinculación de un vehículo por cambio de dueño | C21: Si | D21: Si | E21: Si | F21: Si | G21: Si | H21: Si
A22: HU-17 | B22: Reenviar o regenerar un código de vinculación | C22: Si | D22: Si | E22: Si | F22: Si | G22: Si | H22: Si | I22: Reclasificada a Must en la v3.0: es el único camino de recuperación cuando el código se pierde, se bloquea tras 3 intentos o vence a los 7 días. Sin ella, un cliente bloqueado no puede vincularse nunca.
A23: HU-18 | B23: Desactivar un cliente | C23: Si | D23: Si | E23: Si | F23: Si | G23: Si | H23: Si
A24: HU-19 | B24: Registrar la entrada de un vehículo afiliado | C24: Si | D24: Si | E24: Si | F24: Si | G24: Si | H24: Si | I24: Depende de HU-07, HU-09 y HU-12a en el orden de construcción, pero entrega valor por si sola: registrar un ingreso ya sustituye el cuaderno.
A25: HU-20 | B25: Registrar la entrada de un visitante ocasional | C25: Si | D25: Si | E25: Si | F25: Si | G25: Si | H25: Si
A26: HU-21 | B26: Registrar la salida y calcular el cobro automáticamente | C26: Si | D26: Si | E26: Si | F26: Si | G26: Revisar | H26: Si | I26: 8 puntos, la historia más grande del backlog. Se mantiene UNIDA por decisión del equipo (14/08/2026): dividirla en cerrar movimiento y calcular cobro dejaría una primera mitad que libera la celda sin cobrar nada, lo cual no es un incremento entregable. Concentra RN-03, RN-10, RN-14 y RN-15.
A27: HU-22 | B27: Anular o corregir un movimiento mal registrado | C27: Si | D27: Si | E27: Si | F27: Si | G27: Si | H27: Si
A28: HU-23 | B28: Consultar que vehículos están adentro en este momento | C28: Si | D28: Si | E28: Si | F28: Si | G28: Si | H28: Si
A29: HU-24 | B29: Registrar el pago de una mensualidad | C29: Si | D29: Si | E29: Si | F29: Si | G29: Si | H29: Si
A30: HU-25 | B30: Ver el estado de cartera de mis clientes | C30: Si | D30: Si | E30: Si | F30: Si | G30: Si | H30: Si
A31: HU-26 | B31: Consultar el historial de pagos de un cliente | C31: Si | D31: Si | E31: Si | F31: Si | G31: Si | H31: Si
A32: HU-27 | B32: Generar carta de cobro en PDF | C32: Si | D32: Si | E32: Si | F32: Si | G32: Si | H32: Si
A33: HU-28 | B33: Ver el historial de entradas y salidas de mi vehículo | C33: Si | D33: Si | E33: Si | F33: Si | G33: Si | H33: Si
A34: HU-29 | B34: Ver el estado de mi mensualidad | C34: Si | D34: Si | E34: Si | F34: Si | G34: Si | H34: Si
A35: HU-30 | B35: Consultar mis pagos registrados | C35: Si | D35: Si | E35: Si | F35: Si | G35: Si | H35: Si
A36: HU-32 | B36: Generar el reporte de ingresos por rango de fechas | C36: Si | D36: Si | E36: Si | F36: Si | G36: Si | H36: Si
A37: HU-33 | B37: Generar el reporte de ocupación | C37: Si | D37: Si | E37: Si | F37: Si | G37: Si | H37: Si
A38: HU-34 | B38: Generar el reporte de vehículos y movimientos | C38: Si | D38: Si | E38: Si | F38: Si | G38: Si | H38: Si
... A40: HU-36 | B40: Consultar la bitácora de auditoría de mi parqueadero | C40: Si | D40: Si | E40: Si | F40: Si | G40: Si | H40: Si
A41: HU-37 | B41: Solicitar la eliminación de mis datos personales | C41: Si | D41: Si | E41: Si | F41: Si | G41: Si | H41: Si | I41: Resuelto en la v3.0: la historia pasa de eliminar a inhabilitar y luego anonimizar (ADR-007), con lo cual el alcance queda cerrado y la historia es estimable y testeable.
A42: HU-38 | B42: Registrar un operario para mi parqueadero | C42: Si | D42: Si | E42: Si | F42: Si | G42: Si | H42: Si
...

Sheet Trazabilidad
A1: Matriz de trazabilidad
A2: Cadena Necesidad -> Stakeholder -> Épica -> Historia -> Regla o RNF -> Caso de prueba. La ultima columna se completa en la fase de Pruebas y ajustes (01/12/2026 - 22/12/2026 según el cronograma del Acta de Constitución).
A4: ID | B4: Necesidad del negocio | C4: Origen | D4: Stakeholder | E4: Épicas | F4: Historias | G4: Reglas / RNF | H4: Casos de prueba
A5: NEC-01 | B5: Eliminar el control manual en papel de las entradas y salidas de vehículos | C5: Acta de Constitución, Antecedentes y Justificación | D5: STK-01, STK-02 | E5: EP-02, EP-04 | F5: HU-07, HU-08, HU-19, HU-20, HU-21, HU-23, HU-43, HU-44, HU-45 | G5: RN-01, RN-10, RN-16, RNF-08, RNF-11 | H5: Por definir
A6: NEC-02 | B6: Cobrar el valor exacto sin cálculos manuales ni discusiones con el cliente | C6: Acta de Constitución, Objetivo Específico 5 | D6: STK-01, STK-03 | E6: EP-02, EP-04 | F6: HU-09, HU-11, HU-21, HU-22 | G6: RN-02, RN-03, RN-13, RN-14 | H6: Por definir
A7: NEC-03 | B7: Saber en todo momento quién está al día y quién está en mora, y poder cobrar a tiempo | C7: Acta de Constitución, Objetivo Específico 5 | D7: STK-01 | E7: EP-05 | F7: HU-24, HU-25, HU-26, HU-27, HU-47 | G7: RN-11, RN-12, RN-13 | H7: Por definir
A8: NEC-04 | B8: Dar transparencia al cliente sobre su propio uso y su estado de cuenta | C8: Acta de Constitución, Objetivo Específico 6 | D8: STK-03 | E8: EP-06 | F8: HU-28, HU-29, HU-30 | G8: RN-07, RN-12, RNF-03 | H8: Por definir
A9: NEC-05 | B9: Entender el desempeño del negocio con datos y no con percepción | C9: Acta de Constitución, Objetivo Específico 7 | D9: STK-01 | E9: EP-07 | F9: HU-32, HU-33, HU-34 | G9: RN-13, RNF-06 | H9: Por definir
A10: NEC-06 | B10: Permitir que varios parqueaderos independientes usen la plataforma sin verse entre si | C10: Acta de Constitución, Alcance Incluido + ADR-001 | D10: STK-01 | E10: EP-01, EP-03 | F10: HU-01, HU-02, HU-03, HU-12a, HU-12b, HU-13, HU-14 | G10: RN-04, RN-05, RN-06, RNF-02 | H10: Por definir
A11: NEC-07 | B11: Cumplir la protección de datos personales y poder auditar toda operación sobre dinero | C11: Análisis de Seguridad (R1, R4, R5) + Ley 1581 de 2012 | D11: STK-01, STK-03 | E11: EP-08 | F11: HU-22, HU-35, HU-36, HU-37 | G11: RN-08, RN-09, RN-13, RNF-05, RNF-07 | H11: Por definir
A12: NEC-08 | B12: Permitir que el operario de turno registre los movimientos sin ver información del negocio que no le corresponde | C12: Acta de Constitución, Objetivo General y Específico 2 + Stakeholders STK-02 | D12: STK-01, STK-02 | E12: EP-01, EP-04 | F12: HU-03, HU-19, HU-20, HU-21, HU-23, HU-38, HU-39, HU-43, HU-44, HU-45 | G12: RN-09, RNF-02, RNF-03, RNF-07, RNF-08 | H12: Por definir
A13: NEC-09 | B13: Atender al cliente de paso sin obligarlo a registrarse y dejarlo consultar lo que va a pagar | C13: Stakeholders STK-04, Necesidad y Expectativa | D13: STK-04 | E13: EP-04 | F13: HU-20, HU-21, HU-40 | G13: RN-06, RN-14, RN-15, RNF-05 | H13: Por definir
A14: NEC-10 | B14: Proteger el código fuente y la documentación generada por el sistema | C14: Análisis de Seguridad (R3, R5) | D14: STK-05 | E14: Transversal | F14: HU-27, HU-36 | G14: RNF-04, RNF-07, RNF-10 | H14: Por definir
A15: NEC-11 | B15: Mantener al día la información del parqueadero y de las afiliaciones a lo largo del tiempo: segundo vehículo, cambio de dueño y retiro de un cliente | C15: Acta de Constitución, Objetivo Específico 1 (modelo de datos) | D15: STK-01 | E15: EP-02, EP-03 | F15: HU-10, HU-15, HU-16, HU-17, HU-18, HU-41, HU-42 | G15: RN-04, RN-06, RN-07, RNF-07, RNF-08 | H15: Por definir
A16: NEC-12 | B16: Que cada usuario gestione su propio acceso y sus credenciales sin depender de otra persona | C16: Acta de Constitución, Objetivo Específico 2 (autenticación y autorización) | D16: STK-01, STK-02, STK-03 | E16: EP-01 | F16: HU-04, HU-05, HU-06, HU-46 | G16: RN-09, RNF-01, RNF-04 | H16: Por definir

Sheet Decisiones (ADR)
A1: Decisiones de arquitectura registradas
A2: Una decisión sin alternativas evaluadas no es un ADR, es una nota. Las siete decisiones de reglas de negocio y de arquitectura funcional están Aceptadas: al 14/08/2026 no queda ninguna decisión de negocio abierta. Queda pendiente ADR-008 sobre el stack tecnológico (lenguaje de servidor y framework), que se registra en la fase de Diseño y arquitectura.
A4: ID | B4: Decisión | C4: Estado | D4: Contexto (que problema resuelve) | E4: Decisión tomada | F4: Alternativas evaluadas y descartadas | G4: Consecuencias
A5: ADR-001 | B5: Estrategia de multi-tenencia | C5: Aceptada | D5: Se quiere poder ofrecer la plataforma a varios parqueaderos independientes, cada uno con su propio administrador, sin reinstalar el sistema para cada uno. El Acta de Constitución lo confirma: el sistema permitirá administrar uno o varios parqueaderos. | E5: Base de datos compartida con discriminador de inquilino: cada tabla operativa lleva parqueadero_id y toda consulta se filtra por el identificador derivado de la sesión. | F5: 1) Una instalación separada por parqueadero: descartada porque cada cliente nuevo exige un despliegue manual y multiplica el mantenimiento. 2) Una base de datos por parqueadero: descartada por complejidad de migraciones y respaldos para el tamaño del equipo. | G5: El sistema soporta N parqueaderos desde el día uno y funciona igual con N=1. Obliga a implementar RNF-02 desde el inicio: un filtro olvidado expone datos de otro parqueadero.
A6: ADR-002 | B6: Mecanismo de vinculación cliente-vehículo-parqueadero | C6: Aceptada | D6: Un cliente que se registra por su cuenta no tiene forma de indicar a que parqueadero pertenece, y el administrador tampoco puede confiar en que la placa que alguien declare sea suya. | E6: Vinculación por placa más código de 6 caracteres emitido por el administrador. El registro del administrador es la fuente de verdad; el cliente solo activa. | F6: 1) Invitación por correo: descartada porque muchos clientes de parqueaderos pequeños no le dan correo al administrador. 2) Autovinculación solo con la placa: descartada porque la placa es pública y cualquiera podría reclamar un vehículo ajeno. | G6: Elimina los duplicados por construcción y resuelve también a que parqueadero se vincula el cliente, porque el código ya pertenece a un parqueadero. Exige gestionar vencimiento y regeneración de códigos (HU-12b, HU-17).
A7: ADR-003 | B7: Modelo de espacios: celdas identificadas | C7: Aceptada (confirmada 14/08/2026) | D7: El backlog v1 guardaba un número total de espacios pero pedía mostrar cuales estaban ocupados, lo cual es imposible con un contador. | E7: Inventario de celdas identificadas con código propio (A-01, A-02) y tipo de vehículo permitido. Confirmado por el Acta de Constitución, que habla expresamente de celdas identificadas y de asociar cada movimiento a una placa y a una celda. | F7: Contador simple de cupos disponibles: más fácil de implementar, pero impide el tablero de ocupación, la asignación de celda al ingreso y el reporte de ocupación por franja. | G7: Habilita HU-08, HU-19, HU-20 y HU-33 tal como están escritas. Costo adicional estimado: 2 a 3 puntos. Se elimina el supuesto SUP-01 de la v2.
